[2023-10-21 21:24:00,166: INFO: main: >>>>>>>> stage Data Ingestion Stage started <<<<<<<]
[2023-10-21 21:24:00,168: INFO: common: yaml file: config/config.yaml loaded successfully]
[2023-10-21 21:24:00,168: INFO: common: yaml file: params.yaml loaded successfully]
[2023-10-21 21:24:00,169: INFO: common: yaml file: schema.yaml loaded successfully]
[2023-10-21 21:24:00,169: INFO: common: created directory at : artifacts]
[2023-10-21 21:24:00,169: ERROR: main: 'ConfigurationManager' object has no attribute 'root_dir']
Traceback (most recent call last):
  File "/Users/sameerraj/Desktop/Machine_learning_python/End-to-End-ML-red-wine-prediction-project/main.py", line 8, in <module>
    data_ingestion.main()
  File "/Users/sameerraj/Desktop/Machine_learning_python/End-to-End-ML-red-wine-prediction-project/src/mlproject/pipeline/stage_01_data_ingestion.py", line 13, in main
    data_ingestion_config=config.get_data_ingestion_config()
                          ^^^^^^^^^^^^^^^^^^^^^^^^^^^^^^^^^^
  File "/Users/sameerraj/Desktop/Machine_learning_python/End-to-End-ML-red-wine-prediction-project/src/mlproject/config/configuration.py", line 19, in get_data_ingestion_config
    create_directories([self.root_dir])
                        ^^^^^^^^^^^^^
AttributeError: 'ConfigurationManager' object has no attribute 'root_dir'
[2023-10-21 21:25:37,482: INFO: main: >>>>>>>> stage Data Ingestion Stage started <<<<<<<]
[2023-10-21 21:25:37,483: INFO: common: yaml file: config/config.yaml loaded successfully]
[2023-10-21 21:25:37,484: INFO: common: yaml file: params.yaml loaded successfully]
[2023-10-21 21:25:37,485: INFO: common: yaml file: schema.yaml loaded successfully]
[2023-10-21 21:25:37,485: INFO: common: created directory at : artifacts]
[2023-10-21 21:25:37,485: INFO: common: created directory at : artifacts/data_ingestion]
[2023-10-21 21:25:38,265: ERROR: main: <urlopen error [SSL: CERTIFICATE_VERIFY_FAILED] certificate verify failed: unable to get local issuer certificate (_ssl.c:1002)>]
Traceback (most recent call last):
  File "/Library/Frameworks/Python.framework/Versions/3.11/lib/python3.11/urllib/request.py", line 1348, in do_open
    h.request(req.get_method(), req.selector, req.data, headers,
  File "/Library/Frameworks/Python.framework/Versions/3.11/lib/python3.11/http/client.py", line 1286, in request
    self._send_request(method, url, body, headers, encode_chunked)
  File "/Library/Frameworks/Python.framework/Versions/3.11/lib/python3.11/http/client.py", line 1332, in _send_request
    self.endheaders(body, encode_chunked=encode_chunked)
  File "/Library/Frameworks/Python.framework/Versions/3.11/lib/python3.11/http/client.py", line 1281, in endheaders
    self._send_output(message_body, encode_chunked=encode_chunked)
  File "/Library/Frameworks/Python.framework/Versions/3.11/lib/python3.11/http/client.py", line 1041, in _send_output
    self.send(msg)
  File "/Library/Frameworks/Python.framework/Versions/3.11/lib/python3.11/http/client.py", line 979, in send
    self.connect()
  File "/Library/Frameworks/Python.framework/Versions/3.11/lib/python3.11/http/client.py", line 1458, in connect
    self.sock = self._context.wrap_socket(self.sock,
                ^^^^^^^^^^^^^^^^^^^^^^^^^^^^^^^^^^^^
  File "/Library/Frameworks/Python.framework/Versions/3.11/lib/python3.11/ssl.py", line 517, in wrap_socket
    return self.sslsocket_class._create(
           ^^^^^^^^^^^^^^^^^^^^^^^^^^^^^
  File "/Library/Frameworks/Python.framework/Versions/3.11/lib/python3.11/ssl.py", line 1075, in _create
    self.do_handshake()
  File "/Library/Frameworks/Python.framework/Versions/3.11/lib/python3.11/ssl.py", line 1346, in do_handshake
    self._sslobj.do_handshake()
ssl.SSLCertVerificationError: [SSL: CERTIFICATE_VERIFY_FAILED] certificate verify failed: unable to get local issuer certificate (_ssl.c:1002)

During handling of the above exception, another exception occurred:

Traceback (most recent call last):
  File "/Users/sameerraj/Desktop/Machine_learning_python/End-to-End-ML-red-wine-prediction-project/main.py", line 8, in <module>
    data_ingestion.main()
  File "/Users/sameerraj/Desktop/Machine_learning_python/End-to-End-ML-red-wine-prediction-project/src/mlproject/pipeline/stage_01_data_ingestion.py", line 15, in main
    data_ingestion.download_file()
  File "/Users/sameerraj/Desktop/Machine_learning_python/End-to-End-ML-red-wine-prediction-project/src/mlproject/components/data_ingestion.py", line 15, in download_file
    filename,headers=requests.urlretrieve(
                     ^^^^^^^^^^^^^^^^^^^^^
  File "/Library/Frameworks/Python.framework/Versions/3.11/lib/python3.11/urllib/request.py", line 241, in urlretrieve
    with contextlib.closing(urlopen(url, data)) as fp:
                            ^^^^^^^^^^^^^^^^^^
  File "/Library/Frameworks/Python.framework/Versions/3.11/lib/python3.11/urllib/request.py", line 216, in urlopen
    return opener.open(url, data, timeout)
           ^^^^^^^^^^^^^^^^^^^^^^^^^^^^^^^
  File "/Library/Frameworks/Python.framework/Versions/3.11/lib/python3.11/urllib/request.py", line 519, in open
    response = self._open(req, data)
               ^^^^^^^^^^^^^^^^^^^^^
  File "/Library/Frameworks/Python.framework/Versions/3.11/lib/python3.11/urllib/request.py", line 536, in _open
    result = self._call_chain(self.handle_open, protocol, protocol +
             ^^^^^^^^^^^^^^^^^^^^^^^^^^^^^^^^^^^^^^^^^^^^^^^^^^^^^^^
  File "/Library/Frameworks/Python.framework/Versions/3.11/lib/python3.11/urllib/request.py", line 496, in _call_chain
    result = func(*args)
             ^^^^^^^^^^^
  File "/Library/Frameworks/Python.framework/Versions/3.11/lib/python3.11/urllib/request.py", line 1391, in https_open
    return self.do_open(http.client.HTTPSConnection, req,
           ^^^^^^^^^^^^^^^^^^^^^^^^^^^^^^^^^^^^^^^^^^^^^^
  File "/Library/Frameworks/Python.framework/Versions/3.11/lib/python3.11/urllib/request.py", line 1351, in do_open
    raise URLError(err)
urllib.error.URLError: <urlopen error [SSL: CERTIFICATE_VERIFY_FAILED] certificate verify failed: unable to get local issuer certificate (_ssl.c:1002)>
